[2025-10-04 17:39:20] [INFO] [INGESTOR] Logging configurato. L'output verrà scritto da capo su 'ingestor.txt'.
[2025-10-04 17:39:20] [INFO] [INGESTOR] Connesso a Redis.
[2025-10-04 17:39:20] [INFO] [INGESTOR] DB: Tentativo di creare la tabella 'Newsletter' (safe=True)...
[2025-10-04 17:39:20] [INFO] [INGESTOR] DB: Assicuro la presenza degli indici...
[2025-10-04 17:39:20] [INFO] [INGESTOR] DB: Inizializzazione e migrazione completate.
[2025-10-04 17:39:20] [INFO] [INGESTOR] Ingestor avviato. Tento di acquisire il lock...
[2025-10-04 17:39:20] [INFO] [INGESTOR] Lock acquisito. Inizio ciclo di controllo...
[2025-10-04 17:39:20] [INFO] [INGESTOR] Token per l'utente esc…com scaduto. Eseguo il refresh...
[2025-10-04 17:39:21] [INFO] [INGESTOR] Token per l'utente esc…com aggiornato e salvato.
[2025-10-04 17:39:24] [INFO] [INGESTOR] Trovate 3 nuove email per esc…com.
[2025-10-04 17:39:25] [INFO] [INGESTOR] Aggiunti 3 lavori alla coda per l'utente esc…com.
[2025-10-04 17:54:06] [INFO] [INGESTOR] Trovate 1 nuove email per esc…com.
[2025-10-04 17:54:06] [INFO] [INGESTOR] Aggiunti 1 lavori alla coda per l'utente esc…com.
[2025-10-04 18:05:37] [INFO] [INGESTOR] Trovate 1 nuove email per esc…com.
[2025-10-04 18:05:37] [INFO] [INGESTOR] Aggiunti 1 lavori alla coda per l'utente esc…com.
[2025-10-04 18:35:53] [INFO] [INGESTOR] Token per l'utente esc…com scaduto. Eseguo il refresh...
[2025-10-04 18:35:53] [INFO] [INGESTOR] Token per l'utente esc…com aggiornato e salvato.
[2025-10-04 19:32:20] [INFO] [INGESTOR] Token per l'utente esc…com scaduto. Eseguo il refresh...
[2025-10-04 19:32:21] [INFO] [INGESTOR] Token per l'utente esc…com aggiornato e salvato.
[2025-10-04 21:33:37] [INFO] [INGESTOR] Token per l'utente esc…com scaduto. Eseguo il refresh...
[2025-10-04 21:33:37] [ERROR] [INGESTOR] Errore imprevisto per l'utente esc…com: HTTPSConnectionPool(host='oauth2.googleapis.com', port=443): Max retries exceeded with url: /token (Caused by NameResolutionError("<urllib3.connection.HTTPSConnection object at 0x000001DCF64520D0>: Failed to resolve 'oauth2.googleapis.com' ([Errno 11001] getaddrinfo failed)"))
Traceback (most recent call last):
  File "C:\Users\francesco.prandi_web\Desktop\newsletter\venv\Lib\site-packages\urllib3\connection.py", line 198, in _new_conn
    sock = connection.create_connection(
        (self._dns_host, self.port),
    ...<2 lines>...
        socket_options=self.socket_options,
    )
  File "C:\Users\francesco.prandi_web\Desktop\newsletter\venv\Lib\site-packages\urllib3\util\connection.py", line 60, in create_connection
    for res in socket.getaddrinfo(host, port, family, socket.SOCK_STREAM):
               ~~~~~~~~~~~~~~~~~~^^^^^^^^^^^^^^^^^^^^^^^^^^^^^^^^^^^^^^^^
  File "C:\Users\francesco.prandi_web\AppData\Local\Programs\Python\Python313\Lib\socket.py", line 975, in getaddrinfo
    for res in _socket.getaddrinfo(host, port, family, type, proto, flags):
               ~~~~~~~~~~~~~~~~~~~^^^^^^^^^^^^^^^^^^^^^^^^^^^^^^^^^^^^^^^^
socket.gaierror: [Errno 11001] getaddrinfo failed

The above exception was the direct cause of the following exception:

Traceback (most recent call last):
  File "C:\Users\francesco.prandi_web\Desktop\newsletter\venv\Lib\site-packages\urllib3\connectionpool.py", line 787, in urlopen
    response = self._make_request(
        conn,
    ...<10 lines>...
        **response_kw,
    )
  File "C:\Users\francesco.prandi_web\Desktop\newsletter\venv\Lib\site-packages\urllib3\connectionpool.py", line 488, in _make_request
    raise new_e
  File "C:\Users\francesco.prandi_web\Desktop\newsletter\venv\Lib\site-packages\urllib3\connectionpool.py", line 464, in _make_request
    self._validate_conn(conn)
    ~~~~~~~~~~~~~~~~~~~^^^^^^
  File "C:\Users\francesco.prandi_web\Desktop\newsletter\venv\Lib\site-packages\urllib3\connectionpool.py", line 1093, in _validate_conn
    conn.connect()
    ~~~~~~~~~~~~^^
  File "C:\Users\francesco.prandi_web\Desktop\newsletter\venv\Lib\site-packages\urllib3\connection.py", line 753, in connect
    self.sock = sock = self._new_conn()
                       ~~~~~~~~~~~~~~^^
  File "C:\Users\francesco.prandi_web\Desktop\newsletter\venv\Lib\site-packages\urllib3\connection.py", line 205, in _new_conn
    raise NameResolutionError(self.host, self, e) from e
urllib3.exceptions.NameResolutionError: <urllib3.connection.HTTPSConnection object at 0x000001DCF64520D0>: Failed to resolve 'oauth2.googleapis.com' ([Errno 11001] getaddrinfo failed)

The above exception was the direct cause of the following exception:

Traceback (most recent call last):
  File "C:\Users\francesco.prandi_web\Desktop\newsletter\venv\Lib\site-packages\requests\adapters.py", line 644, in send
    resp = conn.urlopen(
        method=request.method,
    ...<9 lines>...
        chunked=chunked,
    )
  File "C:\Users\francesco.prandi_web\Desktop\newsletter\venv\Lib\site-packages\urllib3\connectionpool.py", line 841, in urlopen
    retries = retries.increment(
        method, url, error=new_e, _pool=self, _stacktrace=sys.exc_info()[2]
    )
  File "C:\Users\francesco.prandi_web\Desktop\newsletter\venv\Lib\site-packages\urllib3\util\retry.py", line 519, in increment
    raise MaxRetryError(_pool, url, reason) from reason  # type: ignore[arg-type]
    ^^^^^^^^^^^^^^^^^^^^^^^^^^^^^^^^^^^^^^^^^^^^^^^^^^^
urllib3.exceptions.MaxRetryError: HTTPSConnectionPool(host='oauth2.googleapis.com', port=443): Max retries exceeded with url: /token (Caused by NameResolutionError("<urllib3.connection.HTTPSConnection object at 0x000001DCF64520D0>: Failed to resolve 'oauth2.googleapis.com' ([Errno 11001] getaddrinfo failed)"))

During handling of the above exception, another exception occurred:

Traceback (most recent call last):
  File "C:\Users\francesco.prandi_web\Desktop\newsletter\venv\Lib\site-packages\google\auth\transport\requests.py", line 187, in __call__
    response = self.session.request(
        method, url, data=body, headers=headers, timeout=timeout, **kwargs
    )
  File "C:\Users\francesco.prandi_web\Desktop\newsletter\venv\Lib\site-packages\requests\sessions.py", line 589, in request
    resp = self.send(prep, **send_kwargs)
  File "C:\Users\francesco.prandi_web\Desktop\newsletter\venv\Lib\site-packages\requests\sessions.py", line 703, in send
    r = adapter.send(request, **kwargs)
  File "C:\Users\francesco.prandi_web\Desktop\newsletter\venv\Lib\site-packages\requests\adapters.py", line 677, in send
    raise ConnectionError(e, request=request)
requests.exceptions.ConnectionError: HTTPSConnectionPool(host='oauth2.googleapis.com', port=443): Max retries exceeded with url: /token (Caused by NameResolutionError("<urllib3.connection.HTTPSConnection object at 0x000001DCF64520D0>: Failed to resolve 'oauth2.googleapis.com' ([Errno 11001] getaddrinfo failed)"))

The above exception was the direct cause of the following exception:

Traceback (most recent call last):
  File "C:\Users\francesco.prandi_web\Desktop\newsletter\backend\ingestor.py", line 148, in get_new_emails_for_user
    creds.refresh(GoogleAuthRequest())
    ~~~~~~~~~~~~~^^^^^^^^^^^^^^^^^^^^^
  File "C:\Users\francesco.prandi_web\Desktop\newsletter\venv\Lib\site-packages\google\oauth2\credentials.py", line 409, in refresh
    ) = reauth.refresh_grant(
        ~~~~~~~~~~~~~~~~~~~~^
        request,
        ^^^^^^^^
    ...<6 lines>...
        enable_reauth_refresh=self._enable_reauth_refresh,
        ^^^^^^^^^^^^^^^^^^^^^^^^^^^^^^^^^^^^^^^^^^^^^^^^^^
    )
    ^
  File "C:\Users\francesco.prandi_web\Desktop\newsletter\venv\Lib\site-packages\google\oauth2\reauth.py", line 333, in refresh_grant
    response_status_ok, response_data, retryable_error = _client._token_endpoint_request_no_throw(
                                                         ~~~~~~~~~~~~~~~~~~~~~~~~~~~~~~~~~~~~~~~~^
        request, token_uri, body, headers=metrics_header
        ^^^^^^^^^^^^^^^^^^^^^^^^^^^^^^^^^^^^^^^^^^^^^^^^
    )
    ^
  File "C:\Users\francesco.prandi_web\Desktop\newsletter\venv\Lib\site-packages\google\oauth2\_client.py", line 192, in _token_endpoint_request_no_throw
    response = request(
        method="POST", url=token_uri, headers=headers_to_use, body=body, **kwargs
    )
  File "C:\Users\francesco.prandi_web\Desktop\newsletter\venv\Lib\site-packages\google\auth\transport\requests.py", line 194, in __call__
    raise new_exc from caught_exc
google.auth.exceptions.TransportError: HTTPSConnectionPool(host='oauth2.googleapis.com', port=443): Max retries exceeded with url: /token (Caused by NameResolutionError("<urllib3.connection.HTTPSConnection object at 0x000001DCF64520D0>: Failed to resolve 'oauth2.googleapis.com' ([Errno 11001] getaddrinfo failed)"))
[2025-10-04 23:16:15] [INFO] [INGESTOR] Token per l'utente esc…com scaduto. Eseguo il refresh...
[2025-10-04 23:16:15] [ERROR] [INGESTOR] Errore imprevisto per l'utente esc…com: HTTPSConnectionPool(host='oauth2.googleapis.com', port=443): Max retries exceeded with url: /token (Caused by NameResolutionError("<urllib3.connection.HTTPSConnection object at 0x000001DCF6453250>: Failed to resolve 'oauth2.googleapis.com' ([Errno 11001] getaddrinfo failed)"))
Traceback (most recent call last):
  File "C:\Users\francesco.prandi_web\Desktop\newsletter\venv\Lib\site-packages\urllib3\connection.py", line 198, in _new_conn
    sock = connection.create_connection(
        (self._dns_host, self.port),
    ...<2 lines>...
        socket_options=self.socket_options,
    )
  File "C:\Users\francesco.prandi_web\Desktop\newsletter\venv\Lib\site-packages\urllib3\util\connection.py", line 60, in create_connection
    for res in socket.getaddrinfo(host, port, family, socket.SOCK_STREAM):
               ~~~~~~~~~~~~~~~~~~^^^^^^^^^^^^^^^^^^^^^^^^^^^^^^^^^^^^^^^^
  File "C:\Users\francesco.prandi_web\AppData\Local\Programs\Python\Python313\Lib\socket.py", line 975, in getaddrinfo
    for res in _socket.getaddrinfo(host, port, family, type, proto, flags):
               ~~~~~~~~~~~~~~~~~~~^^^^^^^^^^^^^^^^^^^^^^^^^^^^^^^^^^^^^^^^
socket.gaierror: [Errno 11001] getaddrinfo failed

The above exception was the direct cause of the following exception:

Traceback (most recent call last):
  File "C:\Users\francesco.prandi_web\Desktop\newsletter\venv\Lib\site-packages\urllib3\connectionpool.py", line 787, in urlopen
    response = self._make_request(
        conn,
    ...<10 lines>...
        **response_kw,
    )
  File "C:\Users\francesco.prandi_web\Desktop\newsletter\venv\Lib\site-packages\urllib3\connectionpool.py", line 488, in _make_request
    raise new_e
  File "C:\Users\francesco.prandi_web\Desktop\newsletter\venv\Lib\site-packages\urllib3\connectionpool.py", line 464, in _make_request
    self._validate_conn(conn)
    ~~~~~~~~~~~~~~~~~~~^^^^^^
  File "C:\Users\francesco.prandi_web\Desktop\newsletter\venv\Lib\site-packages\urllib3\connectionpool.py", line 1093, in _validate_conn
    conn.connect()
    ~~~~~~~~~~~~^^
  File "C:\Users\francesco.prandi_web\Desktop\newsletter\venv\Lib\site-packages\urllib3\connection.py", line 753, in connect
    self.sock = sock = self._new_conn()
                       ~~~~~~~~~~~~~~^^
  File "C:\Users\francesco.prandi_web\Desktop\newsletter\venv\Lib\site-packages\urllib3\connection.py", line 205, in _new_conn
    raise NameResolutionError(self.host, self, e) from e
urllib3.exceptions.NameResolutionError: <urllib3.connection.HTTPSConnection object at 0x000001DCF6453250>: Failed to resolve 'oauth2.googleapis.com' ([Errno 11001] getaddrinfo failed)

The above exception was the direct cause of the following exception:

Traceback (most recent call last):
  File "C:\Users\francesco.prandi_web\Desktop\newsletter\venv\Lib\site-packages\requests\adapters.py", line 644, in send
    resp = conn.urlopen(
        method=request.method,
    ...<9 lines>...
        chunked=chunked,
    )
  File "C:\Users\francesco.prandi_web\Desktop\newsletter\venv\Lib\site-packages\urllib3\connectionpool.py", line 841, in urlopen
    retries = retries.increment(
        method, url, error=new_e, _pool=self, _stacktrace=sys.exc_info()[2]
    )
  File "C:\Users\francesco.prandi_web\Desktop\newsletter\venv\Lib\site-packages\urllib3\util\retry.py", line 519, in increment
    raise MaxRetryError(_pool, url, reason) from reason  # type: ignore[arg-type]
    ^^^^^^^^^^^^^^^^^^^^^^^^^^^^^^^^^^^^^^^^^^^^^^^^^^^
urllib3.exceptions.MaxRetryError: HTTPSConnectionPool(host='oauth2.googleapis.com', port=443): Max retries exceeded with url: /token (Caused by NameResolutionError("<urllib3.connection.HTTPSConnection object at 0x000001DCF6453250>: Failed to resolve 'oauth2.googleapis.com' ([Errno 11001] getaddrinfo failed)"))

During handling of the above exception, another exception occurred:

Traceback (most recent call last):
  File "C:\Users\francesco.prandi_web\Desktop\newsletter\venv\Lib\site-packages\google\auth\transport\requests.py", line 187, in __call__
    response = self.session.request(
        method, url, data=body, headers=headers, timeout=timeout, **kwargs
    )
  File "C:\Users\francesco.prandi_web\Desktop\newsletter\venv\Lib\site-packages\requests\sessions.py", line 589, in request
    resp = self.send(prep, **send_kwargs)
  File "C:\Users\francesco.prandi_web\Desktop\newsletter\venv\Lib\site-packages\requests\sessions.py", line 703, in send
    r = adapter.send(request, **kwargs)
  File "C:\Users\francesco.prandi_web\Desktop\newsletter\venv\Lib\site-packages\requests\adapters.py", line 677, in send
    raise ConnectionError(e, request=request)
requests.exceptions.ConnectionError: HTTPSConnectionPool(host='oauth2.googleapis.com', port=443): Max retries exceeded with url: /token (Caused by NameResolutionError("<urllib3.connection.HTTPSConnection object at 0x000001DCF6453250>: Failed to resolve 'oauth2.googleapis.com' ([Errno 11001] getaddrinfo failed)"))

The above exception was the direct cause of the following exception:

Traceback (most recent call last):
  File "C:\Users\francesco.prandi_web\Desktop\newsletter\backend\ingestor.py", line 148, in get_new_emails_for_user
    creds.refresh(GoogleAuthRequest())
    ~~~~~~~~~~~~~^^^^^^^^^^^^^^^^^^^^^
  File "C:\Users\francesco.prandi_web\Desktop\newsletter\venv\Lib\site-packages\google\oauth2\credentials.py", line 409, in refresh
    ) = reauth.refresh_grant(
        ~~~~~~~~~~~~~~~~~~~~^
        request,
        ^^^^^^^^
    ...<6 lines>...
        enable_reauth_refresh=self._enable_reauth_refresh,
        ^^^^^^^^^^^^^^^^^^^^^^^^^^^^^^^^^^^^^^^^^^^^^^^^^^
    )
    ^
  File "C:\Users\francesco.prandi_web\Desktop\newsletter\venv\Lib\site-packages\google\oauth2\reauth.py", line 333, in refresh_grant
    response_status_ok, response_data, retryable_error = _client._token_endpoint_request_no_throw(
                                                         ~~~~~~~~~~~~~~~~~~~~~~~~~~~~~~~~~~~~~~~~^
        request, token_uri, body, headers=metrics_header
        ^^^^^^^^^^^^^^^^^^^^^^^^^^^^^^^^^^^^^^^^^^^^^^^^
    )
    ^
  File "C:\Users\francesco.prandi_web\Desktop\newsletter\venv\Lib\site-packages\google\oauth2\_client.py", line 192, in _token_endpoint_request_no_throw
    response = request(
        method="POST", url=token_uri, headers=headers_to_use, body=body, **kwargs
    )
  File "C:\Users\francesco.prandi_web\Desktop\newsletter\venv\Lib\site-packages\google\auth\transport\requests.py", line 194, in __call__
    raise new_exc from caught_exc
google.auth.exceptions.TransportError: HTTPSConnectionPool(host='oauth2.googleapis.com', port=443): Max retries exceeded with url: /token (Caused by NameResolutionError("<urllib3.connection.HTTPSConnection object at 0x000001DCF6453250>: Failed to resolve 'oauth2.googleapis.com' ([Errno 11001] getaddrinfo failed)"))
[2025-10-04 23:17:15] [INFO] [INGESTOR] Token per l'utente esc…com scaduto. Eseguo il refresh...
[2025-10-04 23:17:16] [INFO] [INGESTOR] Token per l'utente esc…com aggiornato e salvato.
[2025-10-04 23:17:19] [INFO] [INGESTOR] Trovate 1 nuove email per esc…com.
[2025-10-04 23:17:19] [INFO] [INGESTOR] Aggiunti 1 lavori alla coda per l'utente esc…com.
[2025-10-04 23:48:52] [INFO] [INGESTOR] Trovate 2 nuove email per esc…com.
[2025-10-04 23:48:53] [INFO] [INGESTOR] Aggiunti 2 lavori alla coda per l'utente esc…com.
[2025-10-04 23:49:56] [INFO] [INGESTOR] Trovate 1 nuove email per esc…com.
[2025-10-04 23:49:56] [INFO] [INGESTOR] Aggiunti 1 lavori alla coda per l'utente esc…com.
[2025-10-05 00:06:39] [INFO] [INGESTOR] Trovate 1 nuove email per esc…com.
[2025-10-05 00:06:39] [INFO] [INGESTOR] Aggiunti 1 lavori alla coda per l'utente esc…com.
